Workbook

Sheet Group Details
A1: SAPM Assignment
A3: Group Details
A4: Name | B4: ID
A5: Kabir Jain | B5: 2023A7PS0542P
A6: Rishi Somani | B6: 2023A1PS0212P
A7: Aditi Sharma | B7: 2023A1PS0184P
A8: Naman Sagtani | B8: 2023A5PS1183P
A11: Company Selected | B11: Tata Elxsi Ltd.
A12: Reason for selection | B12: Tata Elxsi was selected for this project because it is a mid-cap IT company with a unique position in the design and engineering services sector, serving global automotive, healthcare, and technology clients with cutting-edge solutions. Its strong financials, consistent dividend growth, and market leadership within the Tata Group make it an excellent benchmark for studying successful, innovation-driven mid-cap companies in India.

Sheet Part 1 Fundamental Financials
A1: Part 1: Fundamental Financials
A3: Tata Elxsi Ltd.
A4: Industry Classification | B4: IT Services / ER&D / Software development services, system integration & support
A5: Age of Firm | B5: Incorporated in 1989; Operating for 35 years
A6: NIC Code | B6: 62013 (Software Development), 62020 (System Integration)
A7: Market Position | B7: Leading global design and technology services provider
A11: Summary of all required ratios
A12: Ratio | B12: FY 2024-25 | C12: FY 2023-24 | D12: Typical IT/ER&D Industry Average | E12: Better / Worse vs Industry | F12: Brief Interpretation
A13: P/E Ratio | B13: =B48 -> 40.913037 | C13: =C48 -> 60.323481 | D13: ~25–30 | E13: Worse (more expensive) | F13: Trades at a richer multiple than most IT/ER&D peers, implying high expectations baked into price.
A14: EBITDA / Total Assets | B14: =B67/100 -> 0.32134605 | C14: =C67/100 -> 0.36661213 | D14: ~18–22% | E14: Better | F14: Enterprise value per unit of EBITDA is significantly above sector norms, indicating premium valuation.
A15: EV / EBITDA | B15: =B49 -> 27.921212 | C15: =C49 -> 40.979708 | D15: ~16–20 | E15: Worse (more expensive) | F15: Pays a slightly lower yield than many large IT peers despite high payout per share, because price is high.
A16: Intangible Assets / Total Assets | B16: =B80/100 -> 0.0024680137 | C16: =C80/100 -> 0.004217533 | F16: Asset productivity is far superior; the firm converts its asset base into operating profits very efficiently.
A17: Dividend Yield | B17: =B50/100 -> 0.0091208819 | C17: =C50/100 -> 0.010466013 | D17: ~1.2–1.5% | E17: Worse (lower yield) | F17: Keeps more of each rupee of revenue as profit than the typical IT/ER&D company.
A18: Total Liabilities / Total Assets | B18: =B86/100 -> 0.20239985 | C18: =C86/100 -> 0.21378388 | D18: ~16–18% | E18: Better | F18: Overall return on assets is well above sector average, signalling strong operating efficiency.
A19: Source of funding for the company's projects and funding (financing) patterns | B19: In FY 2024–25, the same internal‑funding, low‑debt pattern continued and strengthened. Around 80% of total assets (₹3,58,572 lakhs) were financed by equity (₹2,85,997 lakhs), with liabilities at ~20% and long‑term lease liabilities reduced to ₹13,931 lakhs, again with no material term‑debt. Operating cash flow (~₹81,198 lakhs) easily covered a much lower capex (~₹1,634 lakhs), while financing cash outflows (~₹49,859 lakhs) were mainly higher dividends and lease repayments, confirming that projects are financed out of retained earnings and cash flows rather than external borrowing. | C19: In FY 2023–24, Tata Elxsi’s projects were funded mainly by equity and internal cash flows, with very low external leverage. About 79% of total assets (₹3,18,698 lakhs) were financed by equity (₹2,50,566 lakhs), while liabilities were ~21% and consisted largely of lease and operating liabilities rather than term loans. Net cash from operations (~₹70,123 lakhs) was more than enough to fund capex (~₹8,302 lakhs), and financing cash outflows (~₹42,783 lakhs) were dominated by dividends and lease repayments, indicating no need for fresh debt | F19: Shareholder returns are materially higher than industry, even with low leverage.
A20: Long-term Debt / Total Assets(%) | B20: =B87 -> 3.8852084 | C20: =C87 -> 5.6852854 | D20: ~13–16% | E20: Better | F20: Uses less debt than the average IT firm, giving a very comfortable balance sheet.
A21: Annual Capex / Total Assets | B21: =B76/100 -> 0.004557442 | C21: =C76/100 -> 0.026048252 | D21: ~17–20% | E21: Better | F21: Negligible structural gearing; financial risk from debt is low.
A22: Total Asset Turnover | B22: =B75 -> 1.0399727 | C22: =C75 -> 1.1145799 | D22: ~30–40% | E22: Better (more conservative) | F22: Capital intensity is low; growth is more people/IP-driven than asset-heavy, similar to peers.
A23: Return on Assets (ROA) | B23: =B68/100 -> 0.21890647 | C23: =C68/100 -> 0.24858565 | D23: ~5–10% | E23: Better (less debt) | F23: Much smaller booked intangibles; IP is not aggressively capitalised on the balance sheet.
A24: Growth Rate in Sales (%) | B24: =B70/100 -> 0.049801617 | C24: =C70/100 -> 0.12955776 | D24: ~1–2% | E24: Neutral–slightly lower | F24: Growth has moderated vs both its own history and many peers after sector-wide slowdown.
A25: Gross Profit Margins | B25: =B56/100 -> 0.93599898 | C25: =C56/100 -> 0.94536663 | D25: ~5–10% | E25: Different mix | F25: Very high value‑added nature of services; strong pricing power.
A26: Net Profit Margin | B26: =B58/100 -> 0.21049253 | C26: =C58/100 -> 0.2230308 | D26: ~8–12% | E26: Worse (slower) | F26: Converts earnings to cash well, supporting dividends and optionality for growth.
A27: ROE (DuPont Analysis) | B27: =B93/100 -> 0.27445641 | C27: =C93/100 -> 0.3161798 | D27: ~85–90% | E27: Better
A28: Free Cash Flows (FCF)( Lakhs) | B28: =B102 -> -149789.91 | C28: =C102 -> -137894.28 | D28: absolute, firm‑specific | E28: Better qualitatively
A33: Calculation of all the ratios
A34: Financial Metrics | B34: FY 2024-25 | C34: FY 2023-24 | D34: FY 2022-23 | E34: Source
A35: VALUATION RATIOS
A36: Net Profit (₹ Lakhs) | B36: ='All References'!F52 -> 78493.68 | C36: ='All References'!G52 -> 79223.79 | E36: Income Statement
A37: EPS - Basic (₹) | B37: ='All References'!F59 -> 126.03 | C37: ='All References'!G59 -> 127.21 | E37: Income Statement
A38: EPS - Diluted (₹) | B38: ='All References'!F60 -> 126.01 | C38: ='All References'!G60 -> 127.18 | E38: Income Statement
A39: Total Shares Outstanding | B39: 62284124 | C39: 62276440 | E39: Equity Share Capital in Annual Report
A40: Dividends Paid(Lakhs) | B40: ='All References'!J63 -> 43593.51 | C40: ='All References'!K63 -> 37739.52 | E40: Dividends Paid from Financing Cash Flow Statement
A41: DPS | B41: =B40/B39*100000 -> 69.991367 | C41: =C40/C39*100000 -> 60.599996 | E41: Dividend Paid/Number of Share Outstanding
A42: Adjusted Closing Price of Stock at the end of Fiscal Year | B42: 5156.27 | C42: 7673.75 | D42: 5790.17 | E42: yfinance.com
A43: Long-term Debt | B43: ='All References'!B68 -> 13931.26 | C43: ='All References'!C68 -> 18118.9 | E43: Balance Sheet
A44: Short Term Debt | B44: ='All References'!B73 -> 5297.82 | C44: ='All References'!C73 -> 4279.24 | E44: Balance Sheet
A45: Total Debt | B45: =B43+B44 -> 19229.08 | C45: =C43+C44 -> 22398.14 | E45: Long Term Debt+ Short Term Debt
A46: Market Cap(Lakhs) | B46: =B39*B42/100000 -> 3211537.6 | C46: =C39*C42/100000 -> 4778938.3 | E46: Price*Outstanding Share
A47: Enterprise Value (₹ Lakhs) | B47: =B46+B45-B84 -> 3217239 | C47: =C46+C45-C84 -> 4788012.2 | E47: Market Cap+Total Debt(Long Term+Short Term)-Cash & Cash Equivalent
A48: P/E Ratio | B48: =B42/B37 -> 40.913037 | C48: =C42/C37 -> 60.323481 | E48: Adjusted Closing Price at last trading day of fiscal year /Earnings Per Share
...

Sheet Part 2 Price Movement Analysis
A1: Part 2: Price Movement Analysis
A3: Lifetime High | B3: 10573.23
A4: Lifetime Low | B4: 4700
A5: Current price’s | B5: 5158.5
A6: Current price’s % discount (premium) to lifetime high | B6: =(B3-B5)*100/B3 -> 51.211692
A7: The average volume of shares traded daily over the past 52 weeks | B7: 233084.1
A9: Weekly historical returns over the past one year :-
A10: Week end date | B10: Weekly close (₹) | C10: Weekly return (%)
A11: 45632 | B11: 7396 | C11: –
A12: 45639 | B12: 7364 | C12: -0.43
A13: 45646 | B13: 6922 | C13: -6.01
A14: 45653 | B14: 6886 | C14: -0.52
A15: 45660 | B15: 6648 | C15: -3.46
A16: 45667 | B16: 6001 | C16: -9.71
A17: 45674 | B17: 6212 | C17: 3.52
A18: 45681 | B18: 6373 | C18: 2.59
A19: 45688 | B19: 6336 | C19: -0.58
A20: 45695 | B20: 6371 | C20: 0.55
A21: 45702 | B21: 6285 | C21: -1.35
A22: 45709 | B22: 6198 | C22: -1.39
A23: 45716 | B23: 6265 | C23: 1.08
... A60: 45975 | B60: 5267 | C60: 1.68
A62: Dividend payment history over the past two years – which types of dividends are paid | B62: FY 2023–24: | C62: Final dividend of ₹70 per share (700% on ₹10 face value), declared in April 2024 and paid after the June 2024 record/ex‑date; this is classified as a final cash dividend.
B63: FY 2024–25: | C63: Final dividend of ₹75 per share (750%), recommended by the board in April 2025 and made effective with a June 11, 2025 record date; again, this is a normal final cash dividend.
A64: Stock split history (past two years) | B64: None | C64: No stock split has been carried out in FY 2023‑24 or FY 2024‑25; the face value has remained ₹10 and share‑count changes are negligible, driven by ESOP allotments rather than splits.
A65: Share repurchase (past two years) | B65: None | C65: There is no buyback announcement or execution for Tata Elxsi in the last two financial years in the corporate‑actions or investor‑relations sections. Share count has slightly increased, not decreased, due to ESOPs, which confirms there was no repurchase programme
A66: Mergers and acquisition, any other significant corporate action | B66: None | C66: No major mergers or acquisitions in the last two years; growth has been organic, driven by large strategic contracts and partnerships across automotive (software‑defined vehicles), media and healthcare.
A69: Market reaction to earnings (last 4 quarters, FY24 or FY25)
A70: Quarter (FY) | B70: Result date | C70: Key earnings highlight (revenue / profit) | D70: Dividend / guidance highlight | E70: Market reaction around results (1–3 days) | F70: Interpretation
A71: Q4 FY25 | B71: 17 Apr 2025 , stock move noted 21 Apr 2025 | C71: Revenue about ₹908 crore, down ~3% QoQ and roughly flat YoY; PAT down ~13% QoQ to ~₹172 crore, margins compressed vs prior quarter. | D71: Board recommended final dividend of ₹75 per share (750% of face value) for FY25. | E71: Intraday, share price jumped roughly 5–5.5% after results and dividend announcement, but subsequent days saw only limited net upside as concerns on margin pressure remained. | F71: Positive knee‑jerk reaction to high dividend and stable full‑year numbers, but overall sentiment cautious due to declining QoQ profit and margin compression.
A72: Q3 FY25 | B72: 45665 | C72: Revenue around ₹939 crore; operating profit and PBT at a five‑quarter low, with margins under pressure vs earlier quarters. | D72: No new dividend; management commentary focused on deal wins and investments in digital/AI to drive future growth. | E72: Stock fell on or shortly after results (reports mention the share sinking ~5–7% intraday as weaker profitability surprised the market). | F72: Clearly negative reaction: investors punished deteriorating profitability despite steady topline and pipeline commentary.
A73: Q2 FY25 | B73: 45575 | C73: Q2 revenue broadly stable with low single‑digit growth YoY, but transportation and media segments soft, leading to slower overall growth and some margin slippage. | D73: No interim dividend; commentary stressed cost discipline and medium‑term deal pipeline. | E73: Price response muted to mildly negative over the 1–3 day window, with the stock drifting lower as numbers were seen as “in line to slightly weak”. | F73: Market reaction was neutral‑to‑negative: results were not bad but not strong enough to reverse the ongoing de‑rating.
A74: Q1 FY25 | B74: 45483 | C74: Revenue and PAT up modestly YoY but flat to slightly down QoQ; continued headwinds in key export verticals. | D74: No dividend; management reiterated focus on large deals and diversification. | E74: Stock showed small negative to flat movement after results, with no sustained rally, reflecting already rich multiples and cautious outlook. | F74: Reaction broadly muted: earnings did not trigger buying interest, reinforcing the narrative of valuation compression despite okay fundamentals.

Sheet Part 3 Portfolio Analysis
A1: Part 3: Portfolio Analysis
A2: Portfolio Construction
A3: Portfolio Size: 1 Crore | H3: Bench Mark Index
A4: Stock Name | B4: Tata Elxsi | C4: Reliance Industries | D4: HDFC Bank | E4: Infosys | F4: Trent Ltd. | G4: Overall Portfolio Performance Summary | H4: NIFTY 50 Index | I4: Inference | J4: Extra Information
A5: Sector | B5: IT + Design + ER&D | C5: Conglomerate (Energy + Retail + Telecom) | D5: BFSI | E5: IT & Services | F5: Retail | G5: Multi-Sector Portfolio (IT + Energy + BFSI + IT Services + Retail) | H5: Broad Market Index – Represents top 50 Indian companies across 14 sectors | I5: The portfolio is intentionally diversified across IT, Conglomerates, BFSI, IT Services, and Retail. This cross-sector allocation helps reduce unsystematic risk and ensures that no single industry dominates portfolio volatility.
A6: Notes | B6: High growth, high volatility | C6: Low-risk anchor, stable returns | D6: Low volatility, steady compounder | E6: Stable large-cap IT | F6: High growth potential but higher valuation | G6: Represents the combined outcome of all five selected stocks and gives a consolidated summary of the portfolio’s overall performance. | H6: Chosen as benchmark because it aligns with the portfolio’s sector composition and contains large-cap stocks similar to Reliance, HDFC Bank, Infosys
A7: Market Cap(crores) | B7: 55491 | C7: 1781841 | D7: 820000 | E7: 791100 | F7: 48044 | G7: =SUM(B7:F7) -> 3496476 | I7: Market capitalization estimates a company's value by extrapolating what the market thinks it is worth for publicly traded companies and multiplying the share price by the number of available shares.
A8: Weight(%) | B8: 30 | C8: =0.7*C7/($G$7-$B$7)*100 -> 36.248013 | D8: =0.7*D7/($G$7-$B$7)*100 -> 16.68127 | E8: =0.7*E7/($G$7-$B$7)*100 -> 16.093357 | F8: =0.7*F7/($G$7-$B$7)*100 -> 0.97735968 | G8: =SUM(B8:F8) -> 100 | I8: The 30% allocation to Tata Elxsi reflects its role as the primary stock. Remaining weights are value-weighted across four stable large-cap companies, improving diversification while maintaining exposure to high-growth sectors.
A9: Amount Invested in each stock as on 1 April 2022 | B9: =100000*B8 -> 3000000 | C9: =100000*C8 -> 3624801.3 | D9: =100000*D8 -> 1668127 | E9: =100000*E8 -> 1609335.7 | F9: =100000*F8 -> 97735.968 | G9: =SUM(B9:F9) -> 10000000 | I9: By allocating capital based on initial weights on 1 April 2022 and avoiding rebalancing, the analysis captures the true impact of market movements on long-term portfolio behavior, as instructed.
A10: Number of Shares Purchased on 1 April 2022 | B10: =B9/B13 -> 348.17959 | C10: =C9/C13 -> 2999.5618 | D10: =D9/D13 -> 2328.7777 | E10: =E9/E13 -> 941.77753 | F10: =F9/F13 -> 77.366715 | G10: =SUM(B10:F10) -> 6695.6633 | I10: Amount Invested/Adjusted Closing Price at 1 April 2022. Since portfolio need not to be rebalanced, it will remain constant throughout the time. | J10: Number of shares= Amount invested/Adjusted Closing Price of that stock
A12: Value of Portfolio on different dates
A13: Adjusted Closing Price as on 1 April 2022 | B13: 8616.2432 | C13: 1208.4436 | D13: 716.31012 | E13: 1708.8279 | F13: 1263.2819 | H13: 17670.449 | I13: Adjusted closing prices correctly incorporate splits/dividends and therefore provide an accurate basis for calculating returns, ensuring that performance is not overstated or understated due to corporate actions.
A14: Adjusted Closing Price as on 30 December 2022 | B14: 6107.7002 | C14: 1162.7881 | D14: 783.41327 | E14: 1383.2114 | F14: 1347.2737 | H14: 18105.301
A15: Adjusted Closing Price as on 2 January 2023 | B15: 6121.7891 | C15: 1175.8896 | D15: 783.67786 | E15: 1397.7021 | F15: 1338.1016 | H15: 18197.449
A16: Adjusted Closing Price as on 29 December 2023 | B16: 8571.9746 | C16: 1282.9791 | D16: 831.86755 | E16: 1452.6169 | F16: 3050.2129 | H16: 21731.4
A17: Adjusted Closing Price as on 1 January 2024 | B17: 8562.916 | C17: 1285.6097 | D17: 826.44104 | E17: 1460.5726 | F17: 2997.4451 | H17: 21741.9
A18: Adjusted Closing Price as on 31 December 2024 | B18: 6720.5254 | C18: 1210.6149 | D18: 874.60303 | E18: 1825.9618 | F18: 7117.1841 | H18: 23644.801
A19: Adjusted Closing Price as on 1 January 2025 | B19: 6668.3164 | C19: 1216.3918 | D19: 879.48694 | E19: 1828.39 | F19: 7061.9316 | H19: 23742.9
A20: Adjusted Closing Price as on 28 November 2025 | B20: 5158.5 | C20: 1567.5 | D20: 1007.6 | E20: 1560.1 | F20: 4250.3999 | H20: 26202.949
A21: Value at 1 April 2022 | B21: =B$10*B13 -> 3000000 | C21: =C$10*C13 -> 3624801.3 | D21: =D$10*D13 -> 1668127 | E21: =E$10*E13 -> 1609335.7 | F21: =F$10*F13 -> 97735.968 | G21: =SUM(B21:F21) -> 10000000 | H21: 17670.449 | I21: Initial values are computed based on number of shares purchased. This establishes the portfolio’s cost base and is essential for accurate return measurement. | J21: Value=Adjusted market price*Number of stocks in portfolio
A22: Value at 30 December 2022 | B22: =B$10*B14 -> 2126576.5 | C22: =C$10*C14 -> 3487854.8 | D22: =D$10*D14 -> 1824395.3 | E22: =E$10*E14 -> 1302677.4 | F22: =F$10*F14 -> 104234.14 | G22: =SUM(B22:F22) -> 8845738.2 | H22: 18105.301 | I22: Changes in portfolio value over each semi-annual period reflect both stock-specific performance and broader market conditions. The portfolio shows periods of recovery and drawdown, consistent with overall market volatility over 2022–2025. The large fluctuations in Tata Elxsi and Trent Ltd. significantly influence total portfolio movement due to their higher volatility and growth orientation. HDFC Bank and Reliance provide stability, moderating extreme downside periods.
A23: Value at 2 January 2023 | B23: =B$10*B15 -> 2131482 | C23: =C$10*C15 -> 3527153.7 | D23: =D$10*D15 -> 1825011.5 | E23: =E$10*E15 -> 1316324.5 | F23: =F$10*F15 -> 103524.52 | G23: =SUM(B23:F23) -> 8903496.2 | H23: 18197.449
A24: Value at 29 December 2023 | B24: =B$10*B16 -> 2984586.6 | C24: =C$10*C16 -> 3848375.2 | D24: =D$10*D16 -> 1937234.6 | E24: =E$10*E16 -> 1368042 | F24: =F$10*F16 -> 235984.95 | G24: =SUM(B24:F24) -> 10374223 | H24: 21731.4
A25: Value at 1 January 2024 | B25: =B$10*B17 -> 2981432.6 | C25: =C$10*C17 -> 3856265.9 | D25: =D$10*D17 -> 1924597.4 | E25: =E$10*E17 -> 1375534.5 | F25: =F$10*F17 -> 231902.48 | G25: =SUM(B25:F25) -> 10369733 | H25: 21741.9
A26: Value at 31 December 2024 | B26: =B$10*B18 -> 2339949.8 | C26: =C$10*C18 -> 3631314.2 | D26: =D$10*D18 -> 2036756 | E26: =E$10*E18 -> 1719649.8 | F26: =F$10*F18 -> 550633.15 | G26: =SUM(B26:F26) -> 10278303 | H26: 23644.801
A27: Value at 1 January 2025 | B27: =B$10*B19 -> 2321771.7 | C27: =C$10*C19 -> 3648642.6 | D27: =D$10*D19 -> 2048129.5 | E27: =E$10*E19 -> 1721936.6 | F27: =F$10*F19 -> 546358.45 | G27: =SUM(B27:F27) -> 10286839 | H27: 23742.9
A28: Value at 28 November 2025 | B28: =B$10*B20 -> 1796084.4 | C28: =C$10*C20 -> 4701813.2 | D28: =D$10*D20 -> 2346476.3 | E28: =E$10*E20 -> 1469267.1 | F28: =F$10*F20 -> 328839.48 | G28: =SUM(B28:F28) -> 10642480 | H28: 26202.949
A30: Returns calculated on basis of different dates
A31: Return from 1 April 2022 to 30 December 2022 (%) | B31: =(B22-B21)/B21*100 -> -29.114115 | C31: =(C22-C21)/C21*100 -> -3.7780429 | D31: =(D22-D21)/D21*100 -> 9.3678907 | E31: =(E22-E21)/E21*100 -> -19.054959 | F31: =(F22-F21)/F21*100 -> 6.6487001 | G31: =(G22-G21)/G21*100 -> -11.542618 | H31: =(H14-H13)/H13*100 -> 2.460897 | I31: In the period from April 2022 to December 2022, the portfolio delivered negative returns. This was mainly due to underperformance of Tata Elxsi, Infosys, and the tech sector, as global IT spending faced a slowdown and high-growth stocks saw major corrections, even though the overall Nifty 50 index posted a slightly positive return thanks to broader sector strength | J31: Answer for Part(a). Analysing Portfolio Performance for each year individually on basis of starting and ending price
A32: Return from 2 January 2023 to 29 December 2023 (%) | B32: =(B24-B23)/B23*100 -> 40.024011 | C32: =(C24-C23)/C23*100 -> 9.1071027 | D32: =(D24-D23)/D23*100 -> 6.1491717 | E32: =(E24-E23)/E23*100 -> 3.928934 | F32: =(F24-F23)/F23*100 -> 127.95078 | G32: =(G24-G23)/G23*100 -> 16.518535 | H32: =(H24-H23)/H23*100 -> 19.420036 | I32: In 2023, the portfolio return was positive but did not outperform the Nifty 50 index. The summary table shows a portfolio return of 16.52%, while the Nifty 50 delivered a higher return of approximately 19.42% during the same period. This means the portfolio underperformed the benchmark in that year, despite positive contributions from stocks such as Reliance Industries and Trent Ltd.
A33: Return from 1 January 2024 to 31 December 2024(%) | B33: =(B26-B25)/B25*100 -> -21.515925 | C33: =(C26-C25)/C25*100 -> -5.8334089 | D33: =(D26-D25)/D25*100 -> 5.8276374 | E33: =(E26-E25)/E25*100 -> 25.016843 | F33: =(F26-F25)/F25*100 -> 137.44169 | G33: =(G26-G25)/G25*100 -> -0.88170095 | H33: =(H26-H25)/H25*100 -> 8.7522266 | I33: In 2024, the portfolio posted a small negative return, underperforming the Nifty 50, which remained positive. The drag was again due to IT stocks such as Tata Elxsi and Infosys struggling with weak global demand and higher valuations, and Trent Ltd facing valuation corrections after strong prior years, whereas the Nifty index benefited from broad-based gains in financial, energy, and core sector stocks
A34: Return from 1 January 2025 to 28 November 2025(%) | B34: =(B28-B27)/B27*100 -> -22.641643 | C34: =(C28-C27)/C27*100 -> 28.864724 | D34: =(D28-D27)/D27*100 -> 14.566793 | E34: =(E28-E27)/E27*100 -> -14.673567 | F34: =(F28-F27)/F27*100 -> -39.812503 | G34: =(G28-G27)/G27*100 -> 3.4572491 | H34: =(H28-H27)/H27*100 -> 10.361198 | I34: By 2025 year-to-date (till late November), the portfolio generated modest positive returns but lagged behind the Nifty 50, which continued to rise on the back of strong corporate earnings, index heavyweights like Reliance Industries, and broad market optimism. Some concentrated holdings in the portfolio did not keep pace with market leaders despite positive news flow and continued operational growth in large caps.
A36: Returns and Volatilty on the basis of stock price data from 1 April 2022 to 28 November 2025
A37: Average Annualized Return over 3 years(%) | B37: ='Stock Price from 1 April 2022 t'!F911 -> -9.2465164 | C37: ='Stock Price from 1 April 2022 t'!M911 -> 10.09232 | D37: ='Stock Price from 1 April 2022 t'!T911 -> 12.20683 | E37: ='Stock Price from 1 April 2022 t'!AA911 -> 0.51480372 | F37: ='Stock Price from 1 April 2022 t'!AH911 -> 48.880525 | G37: ='Stock Price from 1 April 2022 t'!AJ911 -> 3.013674 | H37: ='Stock Price from 1 April 2022 t'!AS911 -> 12.131737 | I37: The portfolio’s annualized return is about 3.01%, which is clearly below the Nifty 50’s 12.57%, indicating that over 1 April 2022–28 November 2025 the five‑stock allocation has generated positive but substantially lower growth than the broad market index. This gap arises because large negative or low returns from Tata Elxsi, Infosys and Trent have diluted the strong performance from Reliance Industries and HDFC Bank during this period. | J37: Calculation is done in Stock Price from 1 April 2022 to 28 November 2025 Sheet in the end.
A38: Average Annualized Standard Deviation over 3 years(%) | B38: ='Stock Price from 1 April 2022 t'!F912 -> 30.596816 | C38: ='Stock Price from 1 April 2022 t'!M912 -> 21.537311 | D38: ='Stock Price from 1 April 2022 t'!T912 -> 20.028049 | E38: ='Stock Price from 1 April 2022 t'!AA912 -> 24.813128 | F38: ='Stock Price from 1 April 2022 t'!AH912 -> 34.568797 | G38: ='Stock Price from 1 April 2022 t'!AJ912 -> 16.726028 | H38: ='Stock Price from 1 April 2022 t'!AS912 -> 12.901207 | I38: Portfolio volatility is around 16.72%, moderately higher than the Nifty 50’s 12.92%, showing that the portfolio took more risk than the index while delivering lower return. The higher risk is consistent with exposure to volatile IT and retail stocks such as Tata Elxsi, Infosys and Trent, whose prices have swung sharply with changes in global tech demand and domestic consumption themes. | J38: Calculation is done in Stock Price from 1 April 2022 to 28 November 2025 Sheet in the end.
A39: Average Annualised Return from 1 April 2022 to 30 December 2022(%) | B39: =((AVERAGE('Stock Price from 1 April 2022 t'!F6:F191)+1)^252-1)*100 -> -31.950347 | C39: =((AVERAGE('Stock Price from 1 April 2022 t'!M6:M191)+1)^252-1)*100 -> -1.8390761 | D39: =((AVERAGE('Stock Price from 1 April 2022 t'!T6:T191)+1)^252-1)*100 -> 16.349158 | E39: =((AVERAGE('Stock Price from 1 April 2022 t'!AA6:AA191)+1)^252-1)*100 -> -21.947327 | F39: =((AVERAGE('Stock Price from 1 April 2022 t'!AH6:AH191)+1)^252-1)*100 -> 15.173566 | G39: =((AVERAGE('Stock Price from 1 April 2022 t'!AJ6:AJ191)+1)^252-1)*100 -> -12.660312 | H39: =((AVERAGE('Stock Price from 1 April 2022 t'!AS6:AS191)+1)^252-1)*100 -> 4.6003416 | I39: The portfolio delivered a negative annualized return (−12.7%) in 2022, whereas Nifty 50 was slightly positive (about 4.6%), indicating clear underperformance in the first year. Losses stem largely from weak performance of Tata Elxsi and Infosys during the global tech correction, which outweighed relatively better resilience in Reliance and HDFC Bank.
A40: Average Annualised Return from 2 January 2023 to 29 December 2023 (%) | B40: =((AVERAGE('Stock Price from 1 April 2022 t'!F192:F436)+1)^252-1)*100 -> 44.68629 | C40: =((AVERAGE('Stock Price from 1 April 2022 t'!M192:M436)+1)^252-1)*100 -> 12.414669 | D40: =((AVERAGE('Stock Price from 1 April 2022 t'!T192:T436)+1)^252-1)*100 -> 7.9406412 | E40: =((AVERAGE('Stock Price from 1 April 2022 t'!AA192:AA436)+1)^252-1)*100 -> 8.09614 | F40: =((AVERAGE('Stock Price from 1 April 2022 t'!AH192:AH436)+1)^252-1)*100 -> 139.13309 | G40: =((AVERAGE('Stock Price from 1 April 2022 t'!AJ192:AJ436)+1)^252-1)*100 -> 20.571753 | H40: =((AVERAGE('Stock Price from 1 April 2022 t'!AS192:AS436)+1)^252-1)*100 -> 21.224625 | I40: In 2023 the portfolio rebounded to a strong positive annualized return (20.6%) but still slightly lagged Nifty 50’s ~21.2%, meaning stock selection almost but not fully matched the broad market rally. Gains were driven by Reliance, HDFC Bank and especially Trent, which benefited from India’s consumption recovery, while Tata Elxsi’s volatility kept overall returns from surpassing the index.​​
A41: Average Annualised Return from 1 January 2024 to 31 December 2024(%) | B41: =((AVERAGE('Stock Price from 1 April 2022 t'!F437:F682)+1)^252-1)*100 -> -18.155404 | C41: =((AVERAGE('Stock Price from 1 April 2022 t'!M437:M682)+1)^252-1)*100 -> -3.244937 | D41: =((AVERAGE('Stock Price from 1 April 2022 t'!T437:T682)+1)^252-1)*100 -> 7.9181746 | E41: =((AVERAGE('Stock Price from 1 April 2022 t'!AA437:AA682)+1)^252-1)*100 -> 29.687633 | F41: =((AVERAGE('Stock Price from 1 April 2022 t'!AH437:AH682)+1)^252-1)*100 -> 155.23309 | G41: =((AVERAGE('Stock Price from 1 April 2022 t'!AJ437:AJ682)+1)^252-1)*100 -> -0.82566998 | H41: =((AVERAGE('Stock Price from 1 April 2022 t'!AS437:AS682)+1)^252-1)*100 -> 10.241484 | I41: For 2024 the portfolio return turned marginally negative (−0.83%) even as Nifty 50 remained comfortably positive (~10.2%), again signaling underperformance. This reflects another weak phase for IT and high‑beta retail names, with Infosys and Trent showing large swings that offset more stable contributions from Reliance and HDFC Bank.
A42: Average Annualised Return from 1 January 2025 to 28 November 2025(%) | B42: =((AVERAGE('Stock Price from 1 April 2022 t'!F683:F908)+1)^252-1)*100 -> -22.423989 | C42: =((AVERAGE('Stock Price from 1 April 2022 t'!M683:M908)+1)^252-1)*100 -> 36.116918 | D42: =((AVERAGE('Stock Price from 1 April 2022 t'!T683:T908)+1)^252-1)*100 -> 18.50252 | E42: =((AVERAGE('Stock Price from 1 April 2022 t'!AA683:AA908)+1)^252-1)*100 -> -13.342998 | F42: =((AVERAGE('Stock Price from 1 April 2022 t'!AH683:AH908)+1)^252-1)*100 -> -38.982072 | G42: =((AVERAGE('Stock Price from 1 April 2022 t'!AJ683:AJ908)+1)^252-1)*100 -> 3.6824764 | H42: =((AVERAGE('Stock Price from 1 April 2022 t'!AS683:AS908)+1)^252-1)*100 -> 11.147063 | I42: Year‑to‑date 2025, the portfolio has a modest positive annualized return (3.67%) but trails Nifty 50’s 11.15%, so the benchmark continues to outperform sharply. The gap suggests that recent index gains have been driven by broad‑based strength in large‑cap sectors that the five‑stock portfolio does not fully capture, while concentrated positions remain more volatile and less rewarded.
A43: Annualised Volatility from 1 April 2022 to 30 December 2022(%) | B43: =(STDEV('Stock Price from 1 April 2022 t'!F6:F191)*SQRT(252)*100) -> 40.575001 | C43: =(STDEV('Stock Price from 1 April 2022 t'!M6:M191)*SQRT(252)*100) -> 25.884746 | D43: =(STDEV('Stock Price from 1 April 2022 t'!T6:T191)*SQRT(252)*100) -> 24.619298 | E43: =(STDEV('Stock Price from 1 April 2022 t'!AA6:AA191)*SQRT(252)*100) -> 27.945643 | F43: =(STDEV('Stock Price from 1 April 2022 t'!AH6:AH191)*SQRT(252)*100) -> 32.856706 | G43: =(STDEV('Stock Price from 1 April 2022 t'!AJ6:AJ191)*SQRT(252)*100) -> 20.732813 | H43: =(STDEV('Stock Price from 1 April 2022 t'!AS6:AS191)*SQRT(252)*100) -> 15.617384 | I43: Year‑wise, volatility patterns show that 2022 was the most turbulent period, with all stocks exhibiting their highest annualized volatility, in line with post‑COVID policy tightening and tech sector corrections, while 2023 and 2024 see a gradual normalization of risk for most names and for Nifty 50. However, even in the quieter years the portfolio’s volatility remains above the index, which suggests that diversification across only five correlated stocks is not sufficient to bring risk down to market levels.
...

Sheet Stock Price from 1 April 2022 t
A2: Price | B2: Open | C2: Close | D2: Adjusted Close | E2: Volume | F2: Daily Return | H2: Price | I2: Open | J2: Close | K2: Adjusted Close | L2: Volume | M2: Daily Return | O2: Price | P2: Open | Q2: Close | R2: Adjusted Close | S2: Volume | T2: Daily Return | V2: Price | W2: Open | X2: Close | Y2: Adjusted Close | Z2: Volume | AA2: Daily Return | AC2: Price | AD2: Open | AE2: Close | AF2: Adjusted Close | AG2: Volume | AH2: Daily Return | AJ2: Weighted average Daily Return | AK2: Weighted average Daily Return | AN2: Price | AO2: Open | AP2: Close | AQ2: Adjusted Close | AR2: Volume | AS2: Daily Return
A3: Ticker | B3: TATAELXSI.NS | C3: TATAELXSI.NS | D3: TATAELXSI.NS | E3: TATAELXSI.NS | H3: Ticker | I3: RELIANCE.NS | J3: RELIANCE.NS | K3: RELIANCE.NS | L3: RELIANCE.NS | O3: Ticker | P3: HDFCBANK.NS | Q3: HDFCBANK.NS | R3: HDFCBANK.NS | S3: HDFCBANK.NS | V3: Ticker | W3: INFY.NS | X3: INFY.NS | Y3: INFY.NS | Z3: INFY.NS | AC3: Ticker | AD3: TRENT.NS | AE3: TRENT.NS | AF3: TRENT.NS | AG3: TRENT.NS | AJ3: Original Portfolio | AK3: Mimicing Sharpe Ratio Portfolio | AL3: Minimum | AN3: Ticker | AO3: ^NSEI | AP3: ^NSEI | AQ3: ^NSEI | AR3: ^NSEI
A4: Date | H4: Date | O4: Date | V4: Date | AC4: Date | AN4: Date
A5: 44652 | B5: 8884 | C5: 8912.7998 | D5: 8616.2432 | E5: 1414522 | H5: 44652 | I5: 1216.5135 | J5: 1225.6743 | K5: 1208.4436 | L5: 7922880 | O5: 44652 | P5: 738.20001 | Q5: 753 | R5: 716.31012 | S5: 14568556 | V5: 44652 | W5: 1886.85 | X5: 1903.55 | Y5: 1708.8279 | Z5: 6171518 | AC5: 44652 | AD5: 1281 | AE5: 1268.45 | AF5: 1263.2819 | AG5: 491523 | AN5: 44652 | AO5: 17436.9 | AP5: 17670.449 | AQ5: 17670.449 | AR5: 291800
A6: 44655 | B6: 8988 | C6: 9009.7002 | D6: 8709.9199 | E6: 511585 | F6: 0.0109 | H6: 44655 | I6: 1225.4897 | J6: 1229.2971 | K6: 1212.0156 | L6: 7929162 | M6: 0.003 | O6: 44655 | P6: 790 | Q6: 828.40002 | R6: 788.03632 | S6: 97450970 | T6: 0.1001 | V6: 44655 | W6: 1889.75 | X6: 1882.95 | Y6: 1690.335 | Z6: 7364074 | AA6: -0.0108 | AC6: 44655 | AD6: 1256.35 | AE6: 1294.65 | AF6: 1289.3751 | AG6: 762394 | AH6: 0.0207 | AJ6: =(F6*'Part 3 Portfolio Analysis'!$B$8+M6*'Part 3 Portfolio Analysis'!$C$8+T6*'Part 3 Portfolio Analysis'!$D$8+AA6*'Part 3 Portfolio Analysis'!$E$8+AH6*'Part 3 Portfolio Analysis'!$F$8)/100 -> 0.019519623 | AK6: ='Part 3 Portfolio Analysis'!$B$107*F6+M6*'Part 3 Portfolio Analysis'!$C$107+T6*'Part 3 Portfolio Analysis'!$D$107+AA6*'Part 3 Portfolio Analysis'!$E$107+AH6*'Part 3 Portfolio Analysis'!$F$107 -> 0.0225529 | AL6: =F6*'Part 3 Portfolio Analysis'!$B$121+M6*'Part 3 Portfolio Analysis'!$C$121+'Part 3 Portfolio Analysis'!$D$121*T6+AA6*'Part 3 Portfolio Analysis'!$E$121+'Part 3 Portfolio Analysis'!$F$121*AH6 -> 0.02776432 | AN6: 44655 | AO6: 17809.1 | AP6: 18053.4 | AQ6: 18053.4 | AR6: 345500 | AS6: 0.0217
A7: 44656 | B7: 9090 | C7: 8878.3496 | D7: 8582.9414 | E7: 617070 | F7: -0.0146 | H7: 44656 | I7: 1223.4822 | J7: 1211.9216 | K7: 1194.8843 | L7: 13149870 | M7: -0.0141 | O7: 44656 | P7: 833.34998 | Q7: 804.125 | R7: 764.94397 | S7: 30922582 | T7: -0.0293 | V7: 44656 | W7: 1883.8 | X7: 1861.1 | Y7: 1670.7203 | Z7: 5472024 | AA7: -0.0116 | AC7: 44656 | AD7: 1310 | AE7: 1319.2 | AF7: 1313.8251 | AG7: 1337792 | AH7: 0.019 | AJ7: =(F7*'Part 3 Portfolio Analysis'!$B$8+M7*'Part 3 Portfolio Analysis'!$C$8+T7*'Part 3 Portfolio Analysis'!$D$8+AA7*'Part 3 Portfolio Analysis'!$E$8+AH7*'Part 3 Portfolio Analysis'!$F$8)/100 -> -0.016059713 | AK7: ='Part 3 Portfolio Analysis'!$B$107*F7+M7*'Part 3 Portfolio Analysis'!$C$107+T7*'Part 3 Portfolio Analysis'!$D$107+AA7*'Part 3 Portfolio Analysis'!$E$107+AH7*'Part 3 Portfolio Analysis'!$F$107 -> -0.0079548 | AL7: =F7*'Part 3 Portfolio Analysis'!$B$121+M7*'Part 3 Portfolio Analysis'!$C$121+'Part 3 Portfolio Analysis'!$D$121*T7+AA7*'Part 3 Portfolio Analysis'!$E$121+'Part 3 Portfolio Analysis'!$F$121*AH7 -> -0.01690828 | AN7: 44656 | AO7: 18080.6 | AP7: 17957.4 | AQ7: 17957.4 | AR7: 283500 | AS7: -0.0053
A8: 44657 | B8: 8875 | C8: 8893.6504 | D8: 8597.7324 | E8: 372750 | F8: 0.0017 | H8: 44657 | I8: 1193.9463 | J8: 1208.6912 | K8: 1191.6993 | L8: 12257215 | M8: -0.0027 | O8: 44657 | P8: 793.84998 | Q8: 775.42499 | R8: 737.64239 | S8: 27027860 | T8: -0.0357 | V8: 44657 | W8: 1855 | X8: 1828.85 | Y8: 1641.769 | Z8: 5407453 | AA8: -0.0173 | AC8: 44657 | AD8: 1323.55 | AE8: 1328.3 | AF8: 1322.8882 | AG8: 907711 | AH8: 0.0069 | AJ8: =(F8*'Part 3 Portfolio Analysis'!$B$8+M8*'Part 3 Portfolio Analysis'!$C$8+T8*'Part 3 Portfolio Analysis'!$D$8+AA8*'Part 3 Portfolio Analysis'!$E$8+AH8*'Part 3 Portfolio Analysis'!$F$8)/100 -> -0.0091406227 | AK8: ='Part 3 Portfolio Analysis'!$B$107*F8+M8*'Part 3 Portfolio Analysis'!$C$107+T8*'Part 3 Portfolio Analysis'!$D$107+AA8*'Part 3 Portfolio Analysis'!$E$107+AH8*'Part 3 Portfolio Analysis'!$F$107 -> -0.0060638 | AL8: =F8*'Part 3 Portfolio Analysis'!$B$121+M8*'Part 3 Portfolio Analysis'!$C$121+'Part 3 Portfolio Analysis'!$D$121*T8+AA8*'Part 3 Portfolio Analysis'!$E$121+'Part 3 Portfolio Analysis'!$F$121*AH8 -> -0.0139828 | AN8: 44657 | AO8: 17842.75 | AP8: 17807.65 | AQ8: 17807.65 | AR8: 328800 | AS8: -0.0083
A9: 44658 | B9: 8907 | C9: 8747.7998 | D9: 8456.7334 | E9: 343816 | F9: -0.0164 | H9: 44658 | I9: 1197.6382 | J9: 1187.3699 | K9: 1170.6776 | L9: 15496499 | M9: -0.0176 | O9: 44658 | P9: 770.65002 | Q9: 758.375 | R9: 721.42322 | S9: 40781732 | T9: -0.022 | V9: 44658 | W9: 1821.05 | X9: 1811 | Y9: 1625.7451 | Z9: 5797544 | AA9: -0.0098 | AC9: 44658 | AD9: 1336 | AE9: 1307.75 | AF9: 1302.4219 | AG9: 1038577 | AH9: -0.0155 | AJ9: =(F9*'Part 3 Portfolio Analysis'!$B$8+M9*'Part 3 Portfolio Analysis'!$C$8+T9*'Part 3 Portfolio Analysis'!$D$8+AA9*'Part 3 Portfolio Analysis'!$E$8+AH9*'Part 3 Portfolio Analysis'!$F$8)/100 -> -0.016698169 | AK9: ='Part 3 Portfolio Analysis'!$B$107*F9+M9*'Part 3 Portfolio Analysis'!$C$107+T9*'Part 3 Portfolio Analysis'!$D$107+AA9*'Part 3 Portfolio Analysis'!$E$107+AH9*'Part 3 Portfolio Analysis'!$F$107 -> -0.0167568 | AL9: =F9*'Part 3 Portfolio Analysis'!$B$121+M9*'Part 3 Portfolio Analysis'!$C$121+'Part 3 Portfolio Analysis'!$D$121*T9+AA9*'Part 3 Portfolio Analysis'!$E$121+'Part 3 Portfolio Analysis'!$F$121*AH9 -> -0.01708314 | AN9: 44658 | AO9: 17723.301 | AP9: 17639.551 | AQ9: 17639.551 | AR9: 308800 | AS9: -0.0094
A10: 44659 | B10: 8791.5498 | C10: 8685.2002 | D10: 8396.2168 | E10: 778818 | F10: -0.0072 | H10: 44659 | I10: 1181.4396 | J10: 1207.1221 | K10: 1190.1523 | L10: 15152495 | M10: 0.0166 | O10: 44659 | P10: 756.04999 | Q10: 757.32501 | R10: 720.42438 | S10: 41256322 | T10: -0.0014 | V10: 44659 | W10: 1823 | X10: 1814.6 | Y10: 1628.9768 | Z10: 5131446 | AA10: 0.002 | AC10: 44659 | AD10: 1308.2 | AE10: 1269.65 | AF10: 1264.4771 | AG10: 874307 | AH10: -0.0291 | AJ10: =(F10*'Part 3 Portfolio Analysis'!$B$8+M10*'Part 3 Portfolio Analysis'!$C$8+T10*'Part 3 Portfolio Analysis'!$D$8+AA10*'Part 3 Portfolio Analysis'!$E$8+AH10*'Part 3 Portfolio Analysis'!$F$8)/100 -> 0.0036610879 | AK10: ='Part 3 Portfolio Analysis'!$B$107*F10+M10*'Part 3 Portfolio Analysis'!$C$107+T10*'Part 3 Portfolio Analysis'!$D$107+AA10*'Part 3 Portfolio Analysis'!$E$107+AH10*'Part 3 Portfolio Analysis'!$F$107 -> -0.0034504 | AL10: =F10*'Part 3 Portfolio Analysis'!$B$121+M10*'Part 3 Portfolio Analysis'!$C$121+'Part 3 Portfolio Analysis'!$D$121*T10+AA10*'Part 3 Portfolio Analysis'!$E$121+'Part 3 Portfolio Analysis'!$F$121*AH10 -> 0.0056303 | AN10: 44659 | AO10: 17698.15 | AP10: 17784.35 | AQ10: 17784.35 | AR10: 274400 | AS10: 0.0082
A11: 44662 | B11: 8723 | C11: 8711.1504 | D11: 8421.3037 | E11: 420571 | F11: 0.003 | H11: 44662 | I11: 1199.8995 | J11: 1204.6069 | K11: 1187.6726 | L11: 9254209 | M11: -0.0021 | O11: 44662 | P11: 753 | Q11: 748.07501 | R11: 711.62512 | S11: 20799066 | T11: -0.0122 | V11: 44662 | W11: 1814 | X11: 1766.55 | Y11: 1585.842 | Z11: 8248407 | AA11: -0.0265 | AC11: 44662 | AD11: 1279.25 | AE11: 1280.9 | AF11: 1275.6813 | AG11: 509264 | AH11: 0.0089 | AJ11: =(F11*'Part 3 Portfolio Analysis'!$B$8+M11*'Part 3 Portfolio Analysis'!$C$8+T11*'Part 3 Portfolio Analysis'!$D$8+AA11*'Part 3 Portfolio Analysis'!$E$8+AH11*'Part 3 Portfolio Analysis'!$F$8)/100 -> -0.0060740778 | AK11: ='Part 3 Portfolio Analysis'!$B$107*F11+M11*'Part 3 Portfolio Analysis'!$C$107+T11*'Part 3 Portfolio Analysis'!$D$107+AA11*'Part 3 Portfolio Analysis'!$E$107+AH11*'Part 3 Portfolio Analysis'!$F$107 -> -0.0024155 | AL11: =F11*'Part 3 Portfolio Analysis'!$B$121+M11*'Part 3 Portfolio Analysis'!$C$121+'Part 3 Portfolio Analysis'!$D$121*T11+AA11*'Part 3 Portfolio Analysis'!$E$121+'Part 3 Portfolio Analysis'!$F$121*AH11 -> -0.00901978 | AN11: 44662 | AO11: 17740.9 | AP11: 17674.949 | AQ11: 17674.949 | AR11: 251700 | AS11: -0.0062
A12: 44663 | B12: 8740 | C12: 8409.25 | D12: 8129.4487 | E12: 599014 | F12: -0.0347 | H12: 44663 | I12: 1193.9 | J12: 1181.9242 | K12: 1165.3085 | L12: 13217742 | M12: -0.0188 | O12: 44663 | P12: 742 | Q12: 746.75 | R12: 710.36462 | S12: 27435402 | T12: -0.0018 | V12: 44663 | W12: 1757.5 | X12: 1742.45 | Y12: 1564.2074 | Z12: 6456184 | AA12: -0.0136 | AC12: 44663 | AD12: 1275 | AE12: 1250.5 | AF12: 1245.405 | AG12: 845636 | AH12: -0.0237 | AJ12: =(F12*'Part 3 Portfolio Analysis'!$B$8+M12*'Part 3 Portfolio Analysis'!$C$8+T12*'Part 3 Portfolio Analysis'!$D$8+AA12*'Part 3 Portfolio Analysis'!$E$8+AH12*'Part 3 Portfolio Analysis'!$F$8)/100 -> -0.01994522 | AK12: ='Part 3 Portfolio Analysis'!$B$107*F12+M12*'Part 3 Portfolio Analysis'!$C$107+T12*'Part 3 Portfolio Analysis'!$D$107+AA12*'Part 3 Portfolio Analysis'!$E$107+AH12*'Part 3 Portfolio Analysis'!$F$107 -> -0.0197418 | AL12: =F12*'Part 3 Portfolio Analysis'!$B$121+M12*'Part 3 Portfolio Analysis'!$C$121+'Part 3 Portfolio Analysis'!$D$121*T12+AA12*'Part 3 Portfolio Analysis'!$E$121+'Part 3 Portfolio Analysis'!$F$121*AH12 -> -0.01457136 | AN12: 44663 | AO12: 17584.85 | AP12: 17530.301 | AQ12: 17530.301 | AR12: 266000 | AS12: -0.0082
A13: 44664 | B13: 8470 | C13: 8383.7998 | D13: 8104.8462 | E13: 397311 | F13: -0.003 | H13: 44664 | I13: 1188.1313 | J13: 1177.5861 | K13: 1161.0314 | L13: 10354235 | M13: -0.0037 | O13: 44664 | P13: 745 | Q13: 732.47498 | R13: 696.7851 | S13: 28892520 | T13: -0.0191 | V13: 44664 | W13: 1754.95 | X13: 1748.55 | Y13: 1569.6834 | Z13: 6257693 | AA13: 0.0035 | AC13: 44664 | AD13: 1260 | AE13: 1232.8 | AF13: 1227.7771 | AG13: 742352 | AH13: -0.0142 | AJ13: =(F13*'Part 3 Portfolio Analysis'!$B$8+M13*'Part 3 Portfolio Analysis'!$C$8+T13*'Part 3 Portfolio Analysis'!$D$8+AA13*'Part 3 Portfolio Analysis'!$E$8+AH13*'Part 3 Portfolio Analysis'!$F$8)/100 -> -0.0050028166 | AK13: ='Part 3 Portfolio Analysis'!$B$107*F13+M13*'Part 3 Portfolio Analysis'!$C$107+T13*'Part 3 Portfolio Analysis'!$D$107+AA13*'Part 3 Portfolio Analysis'!$E$107+AH13*'Part 3 Portfolio Analysis'!$F$107 -> -0.007887 | AL13: =F13*'Part 3 Portfolio Analysis'!$B$121+M13*'Part 3 Portfolio Analysis'!$C$121+'Part 3 Portfolio Analysis'!$D$121*T13+AA13*'Part 3 Portfolio Analysis'!$E$121+'Part 3 Portfolio Analysis'!$F$121*AH13 -> -0.00666636 | AN13: 44664 | AO13: 17599.9 | AP13: 17475.65 | AQ13: 17475.65 | AR13: 245100 | AS13: -0.0031
A14: 44669 | B14: 8319 | C14: 7815.9502 | D14: 7555.8901 | E14: 685016 | F14: -0.0677 | H14: 44669 | I14: 1168.9791 | J14: 1173.9863 | K14: 1157.4823 | L14: 9974224 | M14: -0.0031 | O14: 44669 | P14: 709.42499 | Q14: 697.72498 | R14: 663.72833 | S14: 45620376 | T14: -0.0474 | V14: 44669 | W14: 1605.5 | X14: 1621.4 | Y14: 1455.5403 | Z14: 30523965 | AA14: -0.0727 | AC14: 44669 | AD14: 1230 | AE14: 1223.5 | AF14: 1218.515 | AG14: 395195 | AH14: -0.0075 | AJ14: =(F14*'Part 3 Portfolio Analysis'!$B$8+M14*'Part 3 Portfolio Analysis'!$C$8+T14*'Part 3 Portfolio Analysis'!$D$8+AA14*'Part 3 Portfolio Analysis'!$E$8+AH14*'Part 3 Portfolio Analysis'!$F$8)/100 -> -0.041113783 | AK14: ='Part 3 Portfolio Analysis'!$B$107*F14+M14*'Part 3 Portfolio Analysis'!$C$107+T14*'Part 3 Portfolio Analysis'!$D$107+AA14*'Part 3 Portfolio Analysis'!$E$107+AH14*'Part 3 Portfolio Analysis'!$F$107 -> -0.0296633 | AL14: =F14*'Part 3 Portfolio Analysis'!$B$121+M14*'Part 3 Portfolio Analysis'!$C$121+'Part 3 Portfolio Analysis'!$D$121*T14+AA14*'Part 3 Portfolio Analysis'!$E$121+'Part 3 Portfolio Analysis'!$F$121*AH14 -> -0.034495 | AN14: 44669 | AO14: 17183.449 | AP14: 17173.65 | AQ14: 17173.65 | AR14: 376100 | AS14: -0.0173
A15: 44670 | B15: 7944 | C15: 7693.1499 | D15: 7437.1758 | E15: 831426 | F15: -0.0157 | H15: 44670 | I15: 1180.5166 | J15: 1218.7288 | K15: 1201.5957 | L15: 26141820 | M15: 0.0381 | O15: 44670 | P15: 690.45001 | Q15: 671.09998 | R15: 638.40063 | S15: 74096022 | T15: -0.0382 | V15: 44670 | W15: 1636.65 | X15: 1562 | Y15: 1402.2163 | Z15: 17044923 | AA15: -0.0366 | AC15: 44670 | AD15: 1244.7 | AE15: 1248.45 | AF15: 1243.3634 | AG15: 1575212 | AH15: 0.0204 | AJ15: =(F15*'Part 3 Portfolio Analysis'!$B$8+M15*'Part 3 Portfolio Analysis'!$C$8+T15*'Part 3 Portfolio Analysis'!$D$8+AA15*'Part 3 Portfolio Analysis'!$E$8+AH15*'Part 3 Portfolio Analysis'!$F$8)/100 -> -0.0029625394 | AK15: ='Part 3 Portfolio Analysis'!$B$107*F15+M15*'Part 3 Portfolio Analysis'!$C$107+T15*'Part 3 Portfolio Analysis'!$D$107+AA15*'Part 3 Portfolio Analysis'!$E$107+AH15*'Part 3 Portfolio Analysis'!$F$107 -> 0.0046591 | AL15: =F15*'Part 3 Portfolio Analysis'!$B$121+M15*'Part 3 Portfolio Analysis'!$C$121+'Part 3 Portfolio Analysis'!$D$121*T15+AA15*'Part 3 Portfolio Analysis'!$E$121+'Part 3 Portfolio Analysis'!$F$121*AH15 -> -0.0024797 | AN15: 44670 | AO15: 17258.949 | AP15: 16958.65 | AQ15: 16958.65 | AR15: 401400 | AS15: -0.0125
A16: 44671 | B16: 7777.9502 | C16: 7807.7002 | D16: 7547.9146 | E16: 676897 | F16: 0.0149 | H16: 44671 | I16: 1226.2512 | J16: 1254.5642 | K16: 1236.9274 | L16: 25072240 | M16: 0.0294 | O16: 44671 | P16: 677.22498 | Q16: 677.15002 | R16: 644.15594 | S16: 49325736 | T16: 0.009 | V16: 44671 | W16: 1575 | X16: 1587.7 | Y16: 1425.2874 | Z16: 10678747 | AA16: 0.0165 | AC16: 44671 | AD16: 1251 | AE16: 1265.9 | AF16: 1260.7423 | AG16: 743805 | AH16: 0.014 | AJ16: =(F16*'Part 3 Portfolio Analysis'!$B$8+M16*'Part 3 Portfolio Analysis'!$C$8+T16*'Part 3 Portfolio Analysis'!$D$8+AA16*'Part 3 Portfolio Analysis'!$E$8+AH16*'Part 3 Portfolio Analysis'!$F$8)/100 -> 0.019420464 | AK16: ='Part 3 Portfolio Analysis'!$B$107*F16+M16*'Part 3 Portfolio Analysis'!$C$107+T16*'Part 3 Portfolio Analysis'!$D$107+AA16*'Part 3 Portfolio Analysis'!$E$107+AH16*'Part 3 Portfolio Analysis'!$F$107 -> 0.0184572 | AL16: =F16*'Part 3 Portfolio Analysis'!$B$121+M16*'Part 3 Portfolio Analysis'!$C$121+'Part 3 Portfolio Analysis'!$D$121*T16+AA16*'Part 3 Portfolio Analysis'!$E$121+'Part 3 Portfolio Analysis'!$F$121*AH16 -> 0.01967582 | AN16: 44671 | AO16: 17045.25 | AP16: 17136.551 | AQ16: 17136.551 | AR16: 286100 | AS16: 0.0105
A17: 44672 | B17: 7940 | C17: 7903.8501 | D17: 7640.8647 | E17: 1376486 | F17: 0.0123 | H17: 44672 | I17: 1269.5399 | J17: 1283.9387 | K17: 1265.8889 | L17: 21708633 | M17: 0.0234 | O17: 44672 | P17: 682.5 | Q17: 687.17499 | R17: 653.69238 | S17: 52446270 | T17: 0.0148 | V17: 44672 | W17: 1595 | X17: 1618.8 | Y17: 1453.2062 | Z17: 7766514 | AA17: 0.0196 | AC17: 44672 | AD17: 1279.85 | AE17: 1285.8 | AF17: 1280.5613 | AG17: 516906 | AH17: 0.0157 | AJ17: =(F17*'Part 3 Portfolio Analysis'!$B$8+M17*'Part 3 Portfolio Analysis'!$C$8+T17*'Part 3 Portfolio Analysis'!$D$8+AA17*'Part 3 Portfolio Analysis'!$E$8+AH17*'Part 3 Portfolio Analysis'!$F$8)/100 -> 0.017948607 | AK17: ='Part 3 Portfolio Analysis'!$B$107*F17+M17*'Part 3 Portfolio Analysis'!$C$107+T17*'Part 3 Portfolio Analysis'!$D$107+AA17*'Part 3 Portfolio Analysis'!$E$107+AH17*'Part 3 Portfolio Analysis'!$F$107 -> 0.0177486 | AL17: =F17*'Part 3 Portfolio Analysis'!$B$121+M17*'Part 3 Portfolio Analysis'!$C$121+'Part 3 Portfolio Analysis'!$D$121*T17+AA17*'Part 3 Portfolio Analysis'!$E$121+'Part 3 Portfolio Analysis'!$F$121*AH17 -> 0.01918664 | AN17: 44672 | AO17: 17234.6 | AP17: 17392.6 | AQ17: 17392.6 | AR17: 285200 | AS17: 0.0149
... A908: 45989 | B908: 5205.5 | C908: 5158.5 | D908: 5158.5 | E908: 136784 | F908: -0.0074 | H908: 45989 | I908: 1568 | J908: 1567.5 | K908: 1567.5 | L908: 8959508 | M908: 0.0026 | O908: 45989 | P908: 1007 | Q908: 1007.6 | R908: 1007.6 | S908: 15988807 | T908: -0.0019 | V908: 45989 | W908: 1565 | X908: 1560.1 | Y908: 1560.1 | Z908: 4453221 | AA908: -0.004 | AC908: 45989 | AD908: 4276.1001 | AE908: 4250.3999 | AF908: 4250.3999 | AG908: 549814 | AH908: -0.0037 | AJ908: =(F908*'Part 3 Portfolio Analysis'!$B$8+M908*'Part 3 Portfolio Analysis'!$C$8+T908*'Part 3 Portfolio Analysis'!$D$8+AA908*'Part 3 Portfolio Analysis'!$E$8+AH908*'Part 3 Portfolio Analysis'!$F$8)/100 -> -0.0022743924 | AK908: ='Part 3 Portfolio Analysis'!$B$107*F908+M908*'Part 3 Portfolio Analysis'!$C$107+T908*'Part 3 Portfolio Analysis'!$D$107+AA908*'Part 3 Portfolio Analysis'!$E$107+AH908*'Part 3 Portfolio Analysis'!$F$107 -> -0.0021451 | AL908: =F908*'Part 3 Portfolio Analysis'!$B$121+M908*'Part 3 Portfolio Analysis'!$C$121+'Part 3 Portfolio Analysis'!$D$121*T908+AA908*'Part 3 Portfolio Analysis'!$E$121+'Part 3 Portfolio Analysis'!$F$121*AH908 -> -0.00093106 | AN908: 45989 | AO908: 26237.449 | AP908: 26202.949 | AQ908: 26202.949 | AR908: 202500 | AS908: -0.0005
A909: Average Daily Return | F909: =AVERAGE(F6:F908) -> -0.00038493909 | M909: =AVERAGE(M6:M908) -> 0.00038161683 | T909: =AVERAGE(T4:T908) -> 0.00045714286 | AA909: =AVERAGE(AA6:AA908) -> 2.0376523e-05 | AH909: =AVERAGE(AH6:AH908) -> 0.0015805094 | AJ909: =AVERAGE(AJ6:AJ908) -> 0.00011783056 | AK909: =AVERAGE(AK6:AK908) -> 0.0005213402 | AL909: =AVERAGE(AL6:AL908) -> 0.00029831194 | AS909: =AVERAGE(AS4:AS908) -> 0.00045448505
A910: Daily Standard Deviation | F910: =STDEV(F6:F908) -> 0.019274183 | M910: =STDEV(M6:M908) -> 0.013567231 | T910: =STDEV(T6:T908) -> 0.012616485 | AA910: =STDEV(AA6:AA908) -> 0.015630802 | AH910: =STDEV(AH6:AH908) -> 0.021776295 | AJ910: =STDEV(AJ6:AJ908) -> 0.010536407 | AK910: =STDEV(AK6:AK908) -> 0.010875384 | AL910: =STDEV(AL6:AL908) -> 0.0098493906 | AS910: =STDEV(AS6:AS908) -> 0.0081269964
A911: Average Annual Return(%) (Assuming 252 Trading Days) | F911: =((1+F909)^252-1)*100 -> -9.2465164 | M911: =((1+M909)^252-1)*100 -> 10.09232 | T911: =((1+T909)^252-1)*100 -> 12.20683 | AA911: =((1+AA909)^252-1)*100 -> 0.51480372 | AH911: =((1+AH909)^252-1)*100 -> 48.880525 | AJ911: =((1+AJ909)^252-1)*100 -> 3.013674 | AK911: =((1+AK909)^252-1)*100 -> 14.035942 | AL911: =((1+AL909)^252-1)*100 -> 7.8060289 | AS911: =((1+AS909)^252-1)*100 -> 12.131737
A912: Average Annual Volatility(%) | F912: =F910*SQRT(252)*100 -> 30.596816 | M912: =M910*SQRT(252)*100 -> 21.537311 | T912: =T910*SQRT(252)*100 -> 20.028049 | AA912: =AA910*SQRT(252)*100 -> 24.813128 | AH912: =AH910*SQRT(252)*100 -> 34.568797 | AJ912: =AJ910*SQRT(252)*100 -> 16.726028 | AK912: =AK910*SQRT(252)*100 -> 17.264137 | AL912: =AL910*SQRT(252)*100 -> 15.635423 | AS912: =AS910*SQRT(252)*100 -> 12.901207

Sheet All References
A1: All References
B2: Link | C2: Type
A3: Part 1: Ratios & Classification | B3: =HYPERLINK("https://www.tataelxsi.com/investors","Tata Elxsi Annual Reports") -> Tata Elxsi Annual Reports | C3: Annual Reports
B4: https://www.niftyindices.com/indices/equity/sectoral-indices/nifty-it | C4: Index data
B5: https://www.screener.in/company/CNXIT/ | C5: Index data
B6: https://www.icra.in/CommonService/OpenMediaS3?Key=df4e31c8-7713-48ae-95e9-b46194039936 | C6: Rating‑agency sector report
B7: https://hr.economictimes.indiatimes.com/news/trends/indian-it-industry-expected-to-grow-3-5-revenue-in-2024-lower-than-2023-report/103151642 | C7: News / industry article
B8: https://www.ibef.org/industry/information-technology-india | C8: Govt/industry profile
B9: https://aventis-advisors.com/it-services-valuation-multiples/ | C9: Valuation study
B10: https://www.moneycontrol.com/indian-indices/nifty-it-19.html | C10: Financial portal
B11: https://ijcrt.org/papers/IJCRT2503524.pdf | C11: Academic paper
B12: https://www.allfinancejournal.com/article/view/284/7-1-14 | C12: Academic paper
A13: Part 2: Price Movement Analysis | B13: https://www.nseindia.com/get-quotes/equity?symbol=TATAELXSI
B14: https://stockpricearchive.com/tata-elxsi-share-price-history/
B15: https://dhan.co/stocks/tata-elxsi-ltd-historical-price/
B16: https://www.tataelxsi.com/news-and-events/press-releases/tata-elxsi-operating-revenue-at-rs-3729-crores-for-fy25-with-full-year-
B17: https://www.tataelxsi.com/news-and-events/press-releases/tata-elxsi-delivers-stable-revenues-in-q3-fy25
B18: https://ijisrt.com/assets/upload/files/IJISRT22MAR995.pdf
A23: Part 3: Portfolio Analysis | B23: https://finance.yahoo.com/quote/TATAELXSI.NS/history/?guccounter=1&guce_referrer=aHR0cHM6Ly93d3cuZ29vZ2xlLmNvbS8&guce_referrer_sig=AQAAAIdCXqiH3EBPXgcBiLRxvbrmIrJYHQ_8okBuuDY1QbviIcAGEThA5yGRHCz9h_6fCG6YDxu78Nfbu2poGzkxTxMliFdX_AKozWh2cqzBSbpuyQEuafAiorwf0dhkpEgp_noMLCy9xbLuh7nkE_F77jPGRjdY4xKa1Da3LLm1_Zn-&period1=1648771200&period2=1764374400
B24: https://finance.yahoo.com/quote/RELIANCE.NS/history/?period1=1648771200&period2=1764374400
B25: https://finance.yahoo.com/quote/HDFCBANK.NS/history/?period1=1648771200&period2=1764374400
B26: https://finance.yahoo.com/quote/INFY.NS/history/?period1=1648771200&period2=1764374400
B27: https://finance.yahoo.com/quote/TRENT.NS/history/?period1=1648771200&period2=1764374400
B28: https://finance.yahoo.com/quote/%5ENSEI/history/?period1=1648771200&period2=1764374400
A34: Balance sheet of Tata Elxsi for the last 2 yrs | E34: Income statement of the company for the last 2 yrs | I34: Cashflow statement of the company for the last 2 yrs
A35: Items | B35: FY 2024-25 (₹ Lakhs) | C35: FY 2023-24 (₹ Lakhs) | E35: Items | F35: FY 2024-25 (₹ Lakhs) | G35: FY 2023-24 (₹ Lakhs) | I35: Items | J35: FY 2024-25 (₹ Lakhs) | K35: FY 2023-24 (₹ Lakhs) | M35: date | N35: close | O35: open | P35: high | Q35: low | R35: volume
A36: ASSETS | E36: Revenue from Operations | F36: 372904.83 | G36: 355214.57 | I36: OPERATING ACTIVITIES | M36: 2024-11-29T00:00:00+05:30 | N36: 6670.75 | O36: 6769.9 | P36: 6779.3 | Q36: 6654.3 | R36: 144216
A37: Non-Current Assets | E37: Other Income (Net) | F37: 17931.15 | G37: 12195.18 | I37: Profit for the Year | J37: 78493.68 | K37: 79223.79 | M37: 2024-12-02T00:00:00+05:30 | N37: 6712.95 | O37: 6670.75 | P37: 6775 | Q37: 6613 | R37: 101706
A38: Property, Plant & Equipment | B38: 15411.48 | C38: 19225.5 | E38: Total Income | F38: 390835.98 | G38: 367409.75 | I38: Tax Expense | J38: 24346.72 | K38: 25643.81 | M38: 2024-12-03T00:00:00+05:30 | N38: 7098.55 | O38: 6750.05 | P38: 7178 | Q38: 6740 | R38: 1080035
A39: Capital Work-in-Progress | B39: 161.73 | C39: 215.43 | I39: Depreciation & Amortisation | J39: 10487.08 | K39: 9944.94 | M39: 2024-12-04T00:00:00+05:30 | N39: 7138.95 | O39: 7124.25 | P39: 7199 | Q39: 7060.4 | R39: 248591
A40: Right of Use Assets | B40: 15507.45 | C40: 19028.05 | E40: Cost of Materials Consumed | F40: 23866.29 | G40: 19406.57 | I40: Share Based Payment Transactions | J40: 1006.93 | K40: 1502.31 | M40: 2024-12-05T00:00:00+05:30 | N40: 7367.75 | O40: 7200 | P40: 7474 | Q40: 7151 | R40: 548868
A41: Intangible Assets | B41: 884.96 | C41: 1344.12 | E41: Changes in Inventories | F41: 110.71 | G41: -72.09 | I41: Interest Income | J41: -11649.15 | K41: -9333.34 | M41: 2024-12-06T00:00:00+05:30 | N41: 7396.45 | O41: 7385.55 | P41: 7429 | Q41: 7324.45 | R41: 169740
A42: Financial Assets - Investments | B42: 0 | C42: 0 | E42: Employee Benefits Expense | F42: 204642.7 | G42: 190959.56 | I42: Finance Costs | J42: 1898.14 | K42: 2026.07 | M42: 2024-12-09T00:00:00+05:30 | N42: 7356 | O42: 7400 | P42: 7460 | Q42: 7320 | R42: 130211
A43: Financial Assets - Other Financial Assets | B43: 39638.81 | C43: 19431.59 | E43: Finance Costs | F43: 1898.14 | G43: 2026.07 | I43: Provision for Doubtful Debts | J43: 584.28 | K43: 16.67 | M43: 2024-12-10T00:00:00+05:30 | N43: 7403.15 | O43: 7325 | P43: 7417.15 | Q43: 7325 | R43: 164865
A44: Deferred Tax Assets (Net) | B44: 3762.62 | C44: 2386.9 | E44: Depreciation & Amortisation | F44: 10487.08 | G44: 9944.94 | I44: Other Adjustments | J44: 1847.8 | K44: 1476.98 | M44: 2024-12-11T00:00:00+05:30 | N44: 7350.25 | O44: 7410 | P44: 7415 | Q44: 7326.65 | R44: 117885
A45: Tax Assets (Net) | B45: 3375.24 | C45: 3239.18 | E45: Other Expenses | F45: 46990.66 | G45: 40277.1 | I45: Operating Profit Before WC Changes | J45: 106015.48 | K45: 109433.57 | M45: 2024-12-12T00:00:00+05:30 | N45: 7319.7 | O45: 7360.05 | P45: 7448.95 | Q45: 7286.5 | R45: 236072
A46: Other Non-Current Assets | B46: 79.65 | C46: 155.31 | E46: Total Expenses | F46: 287995.58 | G46: 262542.15 | I46: Changes in Working Capital | J46: -2817.79 | K46: -13310.24 | M46: 2024-12-13T00:00:00+05:30 | N46: 7364.4 | O46: 7314 | P46: 7414 | Q46: 7211.95 | R46: 170937
A47: Total Non-Current Assets | B47: 78821.94 | C47: 65026.08 | E47: Profit Before Tax | F47: 102840.4 | G47: 104867.6 | I47: Cash Generated from Operations | J47: 103591.01 | K47: 95923.17 | M47: 2024-12-16T00:00:00+05:30 | N47: 7357 | O47: 7372.5 | P47: 7424.35 | Q47: 7317.35 | R47: 76612
E48: Tax Expense | I48: Income Tax Paid (Net) | J48: -22393.32 | K48: -25799.84 | M48: 2024-12-17T00:00:00+05:30 | N48: 7273.65 | O48: 7352 | P48: 7400 | Q48: 7232.6 | R48: 135615
A49: Current Assets | E49: Current Tax Expense | F49: 25466.42 | G49: 26206 | I49: Net Cash from Operating Activities | J49: 81197.69 | K49: 70123.33 | M49: 2024-12-18T00:00:00+05:30 | N49: 7230.55 | O49: 7265 | P49: 7363.5 | Q49: 7214.55 | R49: 159943
...
